Workbook

Sheet PREÇOS MDF
A1: Tipo de MDF | B1: Preço por m² (R$)
A2: MDF - 9MM | B2: 15.44
A3: MDF - 15MM | B3: 23.01
A4: MDF - 25MM | B4: 42.99
A5: MDP - 15MM | B5: 20.57
A7: MDF - 9MM | B7: 15.44
A8: MDF - 15MM | B8: 23.01
A9: MDF - 25MM | B9: 42.99
A10: MDP - 15MM | B10: 20.57

Sheet Controle de Fundos
A2: Lote de Origem | B2: Fábrica | C2: Tipo de Chapa/COR | D2: Comprimento Sobras (mm) | E2: Largura Sobras (mm) | F2: Peça | G2: M² Sobras | H2: Quantidade de Sobra INICIAL | I2: Status da Sobra | J2: Quantidade Aproveitada | K2: Estoque | L2: Local de armazenagem | M2: M² Disponível | N2: Saída | O2: Saída 2 | P2: Saída 3 | Q2: Reaproveitada em OP | R2: Responsável pelo Registro | S2: Data do Registro inical | T2: Dias Parados | U2: média dias parados
A3: - | B3: =VLOOKUP(LEFT(A3,1),Tabela5[],2,0) | C3: EUCADUR FRJ - 2,5MM | D3: 329 | E3: 398 | F3: =TEXT(TabelaSobras8[[#This Row],[Comprimento Sobras (mm)]],0) & " X " & TEXT(E3,0) | G3: =(TabelaSobras8[[#This Row],[Comprimento Sobras (mm)]]*E3/1000000) | H3: 2100 | I3: =IF(TabelaSobras8[[#This Row],[Estoque]]<=$V$2,$U$4,$U$5) | J3: =TabelaSobras8[[#This Row],[Quantidade de Sobra INICIAL]]-K3 | K3: =TabelaSobras8[[#This Row],[Quantidade de Sobra INICIAL]]-TabelaSobras8[[#This Row],[Saída]]-TabelaSobras8[[#This Row],[Saída 2]]-P3 | L3: Nesher | M3: =TabelaSobras8[[#This Row],[Estoque]]*5.8575 | N3: 700 | O3: 700 | P3: 700 | Q3: 700 I25023 700 M25014 700 I25027 | R3: Yuri | S3: 45804 | T3: =INT(TODAY()-TabelaSobras8[[#This Row],[Data do Registro inical]]) | U3: =AVERAGEIF(TabelaSobras8[Status da Sobra],"Disponível",TabelaSobras8[Dias Parados])
A4: - | B4: =VLOOKUP(LEFT(A4,1),Tabela5[],2,0) | C4: EUCADUR FRJ - 2,5MM | D4: 695 | E4: 285 | F4: =TEXT(TabelaSobras8[[#This Row],[Comprimento Sobras (mm)]],0) & " X " & TEXT(E4,0) | G4: =(TabelaSobras8[[#This Row],[Comprimento Sobras (mm)]]*E4/1000000) | H4: 348 | I4: =IF(TabelaSobras8[[#This Row],[Estoque]]<=$V$2,$U$4,$U$5) | J4: =TabelaSobras8[[#This Row],[Quantidade de Sobra INICIAL]]-K4 | K4: =TabelaSobras8[[#This Row],[Quantidade de Sobra INICIAL]]-TabelaSobras8[[#This Row],[Saída]]-TabelaSobras8[[#This Row],[Saída 2]]-P4 | L4: Nesher | M4: =TabelaSobras8[[#This Row],[Estoque]]*5.8575 | N4: 348 | R4: Yuri | S4: 45804 | T4: =INT(TODAY()-TabelaSobras8[[#This Row],[Data do Registro inical]]) | U4: Aproveitada
A5: - | B5: =VLOOKUP(LEFT(A5,1),Tabela5[],2,0) | C5: EUCADUR FRJ - 2,5MM | D5: 514 | E5: 398 | F5: =TEXT(TabelaSobras8[[#This Row],[Comprimento Sobras (mm)]],0) & " X " & TEXT(E5,0) | G5: =(TabelaSobras8[[#This Row],[Comprimento Sobras (mm)]]*E5/1000000) | H5: 120 | I5: =IF(TabelaSobras8[[#This Row],[Estoque]]<=$V$2,$U$4,$U$5) | J5: =TabelaSobras8[[#This Row],[Quantidade de Sobra INICIAL]]-K5 | K5: =TabelaSobras8[[#This Row],[Quantidade de Sobra INICIAL]]-TabelaSobras8[[#This Row],[Saída]]-TabelaSobras8[[#This Row],[Saída 2]]-P5 | L5: Nesher | M5: =TabelaSobras8[[#This Row],[Estoque]]*5.8575 | N5: 120 | Q5: 120 N25043 | R5: Yuri | S5: 45813 | T5: =INT(TODAY()-TabelaSobras8[[#This Row],[Data do Registro inical]]) | U5: Disponível
A6: - | B6: =VLOOKUP(LEFT(A6,1),Tabela5[],2,0) | C6: EUCADUR FRJ - 2,5MM | D6: 629 | E6: 398 | F6: =TEXT(TabelaSobras8[[#This Row],[Comprimento Sobras (mm)]],0) & " X " & TEXT(E6,0) | G6: =(TabelaSobras8[[#This Row],[Comprimento Sobras (mm)]]*E6/1000000) | H6: 799 | I6: =IF(TabelaSobras8[[#This Row],[Estoque]]<=$V$2,$U$4,$U$5) | J6: =TabelaSobras8[[#This Row],[Quantidade de Sobra INICIAL]]-K6 | K6: =TabelaSobras8[[#This Row],[Quantidade de Sobra INICIAL]]-TabelaSobras8[[#This Row],[Saída]]-TabelaSobras8[[#This Row],[Saída 2]]-P6 | L6: Nesher | M6: =TabelaSobras8[[#This Row],[Estoque]]*5.8575 | N6: 799 | Q6: 799 I25027 | R6: Yuri | S6: 45804 | T6: =INT(TODAY()-TabelaSobras8[[#This Row],[Data do Registro inical]])
A7: N | B7: =VLOOKUP(LEFT(A7,1),Tabela5[],2,0) | C7: EUCADUR FRJ - 2,5MM | D7: 655 | E7: 390 | F7: =TEXT(TabelaSobras8[[#This Row],[Comprimento Sobras (mm)]],0) & " X " & TEXT(E7,0) | G7: =(TabelaSobras8[[#This Row],[Comprimento Sobras (mm)]]*E7/1000000) | H7: 250 | I7: =IF(TabelaSobras8[[#This Row],[Estoque]]<=$V$2,$U$4,$U$5) | J7: =TabelaSobras8[[#This Row],[Quantidade de Sobra INICIAL]]-K7 | K7: =TabelaSobras8[[#This Row],[Quantidade de Sobra INICIAL]]-TabelaSobras8[[#This Row],[Saída]]-TabelaSobras8[[#This Row],[Saída 2]]-P7 | L7: Nesher | M7: =TabelaSobras8[[#This Row],[Estoque]]*5.8575 | N7: 250 | Q7: 255 I25028 | R7: Yuri | S7: 45804 | T7: =INT(TODAY()-TabelaSobras8[[#This Row],[Data do Registro inical]])
A8: N | B8: =VLOOKUP(LEFT(A8,1),Tabela5[],2,0) | C8: EUCADUR FRJ - 2,5MM | D8: 1195 | E8: 170 | F8: =TEXT(TabelaSobras8[[#This Row],[Comprimento Sobras (mm)]],0) & " X " & TEXT(E8,0) | G8: =(TabelaSobras8[[#This Row],[Comprimento Sobras (mm)]]*E8/1000000) | H8: =478+70 | I8: =IF(TabelaSobras8[[#This Row],[Estoque]]<=$V$2,$U$4,$U$5) | J8: =TabelaSobras8[[#This Row],[Quantidade de Sobra INICIAL]]-K8 | K8: =TabelaSobras8[[#This Row],[Quantidade de Sobra INICIAL]]-TabelaSobras8[[#This Row],[Saída]]-TabelaSobras8[[#This Row],[Saída 2]]-P8 | L8: Nesher | M8: =TabelaSobras8[[#This Row],[Estoque]]*5.8575 | N8: 350 | O8: 128 | P8: 70 | Q8: 350 N25041 128 N25044 70 M25032 | R8: Yuri | S8: 45804 | T8: =INT(TODAY()-TabelaSobras8[[#This Row],[Data do Registro inical]])
A9: I25027 | B9: =VLOOKUP(LEFT(A9,1),Tabela5[],2,0) | C9: EUCADUR FRJ - 2,5MM | D9: 925 | E9: 375 | F9: =TEXT(TabelaSobras8[[#This Row],[Comprimento Sobras (mm)]],0) & " X " & TEXT(E9,0) | G9: =(TabelaSobras8[[#This Row],[Comprimento Sobras (mm)]]*E9/1000000) | H9: 550 | I9: =IF(TabelaSobras8[[#This Row],[Estoque]]<=$V$2,$U$4,$U$5) | J9: =TabelaSobras8[[#This Row],[Quantidade de Sobra INICIAL]]-K9 | K9: =TabelaSobras8[[#This Row],[Quantidade de Sobra INICIAL]]-TabelaSobras8[[#This Row],[Saída]]-TabelaSobras8[[#This Row],[Saída 2]]-P9 | L9: Nesher | M9: =TabelaSobras8[[#This Row],[Estoque]]*5.8575 | N9: 550 | Q9: 550 N25041 | R9: Yuri | S9: 45804 | T9: =INT(TODAY()-TabelaSobras8[[#This Row],[Data do Registro inical]])
A10: I25028 | B10: =VLOOKUP(LEFT(A10,1),Tabela5[],2,0) | C10: EUCADUR FRJ - 2,5MM | D10: 329 | E10: 398 | F10: =TEXT(TabelaSobras8[[#This Row],[Comprimento Sobras (mm)]],0) & " X " & TEXT(E10,0) | G10: =(TabelaSobras8[[#This Row],[Comprimento Sobras (mm)]]*E10/1000000) | H10: 65 | I10: =IF(TabelaSobras8[[#This Row],[Estoque]]<=$V$2,$U$4,$U$5) | J10: =TabelaSobras8[[#This Row],[Quantidade de Sobra INICIAL]]-K10 | K10: =TabelaSobras8[[#This Row],[Quantidade de Sobra INICIAL]]-TabelaSobras8[[#This Row],[Saída]]-TabelaSobras8[[#This Row],[Saída 2]]-P10 | L10: Nesher | M10: =TabelaSobras8[[#This Row],[Estoque]]*5.8575 | N10: 65 | R10: Yuri | S10: 45806 | T10: =INT(TODAY()-TabelaSobras8[[#This Row],[Data do Registro inical]])
A11: I25028 | B11: =VLOOKUP(LEFT(A11,1),Tabela5[],2,0) | C11: EUCADUR FRJ - 2,5MM | D11: 629 | E11: 398 | F11: =TEXT(TabelaSobras8[[#This Row],[Comprimento Sobras (mm)]],0) & " X " & TEXT(E11,0) | G11: =(TabelaSobras8[[#This Row],[Comprimento Sobras (mm)]]*E11/1000000) | H11: 105 | I11: =IF(TabelaSobras8[[#This Row],[Estoque]]<=$V$2,$U$4,$U$5) | J11: =TabelaSobras8[[#This Row],[Quantidade de Sobra INICIAL]]-K11 | K11: =TabelaSobras8[[#This Row],[Quantidade de Sobra INICIAL]]-TabelaSobras8[[#This Row],[Saída]]-TabelaSobras8[[#This Row],[Saída 2]]-P11 | L11: Nesher | M11: =TabelaSobras8[[#This Row],[Estoque]]*5.8575 | N11: 105 | Q11: N25056 | R11: Yuri | S11: 45806 | T11: =INT(TODAY()-TabelaSobras8[[#This Row],[Data do Registro inical]])
A12: N25041 | B12: =VLOOKUP(LEFT(A12,1),Tabela5[],2,0) | C12: EUCADUR FRJ - 2,5MM | D12: 695 | E12: 330 | F12: =TEXT(TabelaSobras8[[#This Row],[Comprimento Sobras (mm)]],0) & " X " & TEXT(E12,0) | G12: =(TabelaSobras8[[#This Row],[Comprimento Sobras (mm)]]*E12/1000000) | H12: 516 | I12: =IF(TabelaSobras8[[#This Row],[Estoque]]<=$V$2,$U$4,$U$5) | J12: =TabelaSobras8[[#This Row],[Quantidade de Sobra INICIAL]]-K12 | K12: =TabelaSobras8[[#This Row],[Quantidade de Sobra INICIAL]]-TabelaSobras8[[#This Row],[Saída]]-TabelaSobras8[[#This Row],[Saída 2]]-P12 | L12: Nesher | M12: =TabelaSobras8[[#This Row],[Estoque]]*5.8575 | N12: 516 | Q12: 516 N25042 | R12: Yuri | S12: 45810 | T12: =INT(TODAY()-TabelaSobras8[[#This Row],[Data do Registro inical]])
A13: N25041 | B13: =VLOOKUP(LEFT(A13,1),Tabela5[],2,0) | C13: EUCADUR FRJ - 2,5MM | D13: 329 | E13: 398 | F13: =TEXT(TabelaSobras8[[#This Row],[Comprimento Sobras (mm)]],0) & " X " & TEXT(E13,0) | G13: =(TabelaSobras8[[#This Row],[Comprimento Sobras (mm)]]*E13/1000000) | H13: 280 | I13: =IF(TabelaSobras8[[#This Row],[Estoque]]<=$V$2,$U$4,$U$5) | J13: =TabelaSobras8[[#This Row],[Quantidade de Sobra INICIAL]]-K13 | K13: =TabelaSobras8[[#This Row],[Quantidade de Sobra INICIAL]]-TabelaSobras8[[#This Row],[Saída]]-TabelaSobras8[[#This Row],[Saída 2]]-P13 | L13: Nesher | M13: =TabelaSobras8[[#This Row],[Estoque]]*5.8575 | N13: 280 | Q13: 280 N25042 | R13: Yuri | S13: 45810 | T13: =INT(TODAY()-TabelaSobras8[[#This Row],[Data do Registro inical]])
A14: N25043 | B14: =VLOOKUP(LEFT(A14,1),Tabela5[],2,0) | C14: EUCADUR FRJ - 2,5MM | D14: 729 | E14: 398 | F14: =TEXT(TabelaSobras8[[#This Row],[Comprimento Sobras (mm)]],0) & " X " & TEXT(E14,0) | G14: =(TabelaSobras8[[#This Row],[Comprimento Sobras (mm)]]*E14/1000000) | H14: 145 | I14: =IF(TabelaSobras8[[#This Row],[Estoque]]<=$V$2,$U$4,$U$5) | J14: =TabelaSobras8[[#This Row],[Quantidade de Sobra INICIAL]]-K14 | K14: =TabelaSobras8[[#This Row],[Quantidade de Sobra INICIAL]]-TabelaSobras8[[#This Row],[Saída]]-TabelaSobras8[[#This Row],[Saída 2]]-P14 | L14: Nesher | M14: =TabelaSobras8[[#This Row],[Estoque]]*5.8575 | N14: 145 | Q14: N25044 | R14: Yuri | S14: 45813 | T14: =INT(TODAY()-TabelaSobras8[[#This Row],[Data do Registro inical]])
A15: N | B15: =VLOOKUP(LEFT(A15,1),Tabela5[],2,0) | C15: EUCADUR FRJ - 2,5MM | D15: 695 | E15: 190 | F15: =TEXT(TabelaSobras8[[#This Row],[Comprimento Sobras (mm)]],0) & " X " & TEXT(E15,0) | G15: =(TabelaSobras8[[#This Row],[Comprimento Sobras (mm)]]*E15/1000000) | H15: 50 | I15: =IF(TabelaSobras8[[#This Row],[Estoque]]<=$V$2,$U$4,$U$5) | J15: =TabelaSobras8[[#This Row],[Quantidade de Sobra INICIAL]]-K15 | K15: =TabelaSobras8[[#This Row],[Quantidade de Sobra INICIAL]]-TabelaSobras8[[#This Row],[Saída]]-TabelaSobras8[[#This Row],[Saída 2]]-P15 | L15: Nesher | M15: =TabelaSobras8[[#This Row],[Estoque]]*5.8575 | N15: 50 | Q15: N25059 | R15: Yuri | S15: 45809 | T15: =INT(TODAY()-TabelaSobras8[[#This Row],[Data do Registro inical]])
A16: N | B16: =VLOOKUP(LEFT(A16,1),Tabela5[],2,0) | C16: EUCADUR NT - 2,5MM | D16: 729 | E16: 398 | F16: =TEXT(TabelaSobras8[[#This Row],[Comprimento Sobras (mm)]],0) & " X " & TEXT(E16,0) | G16: =(TabelaSobras8[[#This Row],[Comprimento Sobras (mm)]]*E16/1000000) | H16: 1050 | I16: =IF(TabelaSobras8[[#This Row],[Estoque]]<=$V$2,$U$4,$U$5) | J16: =TabelaSobras8[[#This Row],[Quantidade de Sobra INICIAL]]-K16 | K16: =TabelaSobras8[[#This Row],[Quantidade de Sobra INICIAL]]-TabelaSobras8[[#This Row],[Saída]]-TabelaSobras8[[#This Row],[Saída 2]]-P16 | L16: Nesher | M16: =TabelaSobras8[[#This Row],[Estoque]]*5.8575 | N16: 700 | O16: 350 | Q16: 700 N2504704 350 M25023 | R16: Yuri | S16: 45821 | T16: =INT(TODAY()-TabelaSobras8[[#This Row],[Data do Registro inical]])
A17: N | B17: =VLOOKUP(LEFT(A17,1),Tabela5[],2,0) | C17: EUCADUR NT - 2,5MM | D17: 695 | E17: 509 | F17: =TEXT(TabelaSobras8[[#This Row],[Comprimento Sobras (mm)]],0) & " X " & TEXT(E17,0) | G17: =(TabelaSobras8[[#This Row],[Comprimento Sobras (mm)]]*E17/1000000) | H17: 350 | I17: =IF(TabelaSobras8[[#This Row],[Estoque]]<=$V$2,$U$4,$U$5) | J17: =TabelaSobras8[[#This Row],[Quantidade de Sobra INICIAL]]-K17 | K17: =TabelaSobras8[[#This Row],[Quantidade de Sobra INICIAL]]-TabelaSobras8[[#This Row],[Saída]]-TabelaSobras8[[#This Row],[Saída 2]]-P17 | L17: Nesher | M17: =TabelaSobras8[[#This Row],[Estoque]]*5.8575 | N17: 350 | Q17: 350 N2504802 | R17: Yuri | S17: 45821 | T17: =INT(TODAY()-TabelaSobras8[[#This Row],[Data do Registro inical]])
A18: M25037 | B18: =VLOOKUP(LEFT(A18,1),Tabela5[],2,0) | C18: EUCADUR FRJ - 2,5MM | D18: 329 | E18: 398 | F18: =TEXT(TabelaSobras8[[#This Row],[Comprimento Sobras (mm)]],0) & " X " & TEXT(E18,0) | G18: =(TabelaSobras8[[#This Row],[Comprimento Sobras (mm)]]*E18/1000000) | H18: 350 | I18: =IF(TabelaSobras8[[#This Row],[Estoque]]<=$V$2,$U$4,$U$5) | J18: =TabelaSobras8[[#This Row],[Quantidade de Sobra INICIAL]]-K18 | K18: =TabelaSobras8[[#This Row],[Quantidade de Sobra INICIAL]]-TabelaSobras8[[#This Row],[Saída]]-TabelaSobras8[[#This Row],[Saída 2]]-P18 | L18: Multilínea | M18: =TabelaSobras8[[#This Row],[Estoque]]*5.8575 | N18: 350 | Q18: ENVIAR P/NESHER | R18: Yuri | S18: 45881 | T18: =INT(TODAY()-TabelaSobras8[[#This Row],[Data do Registro inical]])
A19: N | B19: =VLOOKUP(LEFT(A19,1),Tabela5[],2,0) | C19: EUCADUR FRJ - 2,5MM | D19: 695 | E19: 312 | F19: =TEXT(TabelaSobras8[[#This Row],[Comprimento Sobras (mm)]],0) & " X " & TEXT(E19,0) | G19: =(TabelaSobras8[[#This Row],[Comprimento Sobras (mm)]]*E19/1000000) | H19: 225 | I19: =IF(TabelaSobras8[[#This Row],[Estoque]]<=$V$2,$U$4,$U$5) | J19: =TabelaSobras8[[#This Row],[Quantidade de Sobra INICIAL]]-K19 | K19: =TabelaSobras8[[#This Row],[Quantidade de Sobra INICIAL]]-TabelaSobras8[[#This Row],[Saída]]-TabelaSobras8[[#This Row],[Saída 2]]-P19 | L19: Nesher | M19: =TabelaSobras8[[#This Row],[Estoque]]*5.8575 | N19: 225 | Q19: N2506801 | R19: Yuri | S19: 45837 | T19: =INT(TODAY()-TabelaSobras8[[#This Row],[Data do Registro inical]])
A20: N | B20: =VLOOKUP(LEFT(A20,1),Tabela5[],2,0) | C20: EUCADUR NT - 2,5MM | D20: 795 | E20: 379 | F20: =TEXT(TabelaSobras8[[#This Row],[Comprimento Sobras (mm)]],0) & " X " & TEXT(E20,0) | G20: =(TabelaSobras8[[#This Row],[Comprimento Sobras (mm)]]*E20/1000000) | H20: 300 | I20: =IF(TabelaSobras8[[#This Row],[Estoque]]<=$V$2,$U$4,$U$5) | J20: =TabelaSobras8[[#This Row],[Quantidade de Sobra INICIAL]]-K20 | K20: =TabelaSobras8[[#This Row],[Quantidade de Sobra INICIAL]]-TabelaSobras8[[#This Row],[Saída]]-TabelaSobras8[[#This Row],[Saída 2]]-P20 | L20: Nesher | M20: =TabelaSobras8[[#This Row],[Estoque]]*5.8575 | N20: 300 | Q20: RECORTE N25050 | R20: Yuri | S20: 45833 | T20: =INT(TODAY()-TabelaSobras8[[#This Row],[Data do Registro inical]])
A21: N | B21: =VLOOKUP(LEFT(A21,1),Tabela5[],2,0) | C21: DURATREE -2,5MM | D21: 795 | E21: 404 | F21: =TEXT(TabelaSobras8[[#This Row],[Comprimento Sobras (mm)]],0) & " X " & TEXT(E21,0) | G21: =(TabelaSobras8[[#This Row],[Comprimento Sobras (mm)]]*E21/1000000) | H21: 152 | I21: =IF(TabelaSobras8[[#This Row],[Estoque]]<=$V$2,$U$4,$U$5) | J21: =TabelaSobras8[[#This Row],[Quantidade de Sobra INICIAL]]-K21 | K21: =TabelaSobras8[[#This Row],[Quantidade de Sobra INICIAL]]-TabelaSobras8[[#This Row],[Saída]]-TabelaSobras8[[#This Row],[Saída 2]]-P21 | L21: Nesher | M21: =TabelaSobras8[[#This Row],[Estoque]]*5.8575 | N21: 152 | Q21: RECORTE NO LOTE M25025 | R21: Yuri | S21: 45833 | T21: =INT(TODAY()-TabelaSobras8[[#This Row],[Data do Registro inical]])
A22: N | B22: =VLOOKUP(LEFT(A22,1),Tabela5[],2,0) | C22: EUCADUR NT - 2,5MM | D22: 540 | E22: 398 | F22: =TEXT(TabelaSobras8[[#This Row],[Comprimento Sobras (mm)]],0) & " X " & TEXT(E22,0) | G22: =(TabelaSobras8[[#This Row],[Comprimento Sobras (mm)]]*E22/1000000) | H22: =640+510 | I22: =IF(TabelaSobras8[[#This Row],[Estoque]]<=$V$2,$U$4,$U$5) | J22: =TabelaSobras8[[#This Row],[Quantidade de Sobra INICIAL]]-K22 | K22: =TabelaSobras8[[#This Row],[Quantidade de Sobra INICIAL]]-TabelaSobras8[[#This Row],[Saída]]-TabelaSobras8[[#This Row],[Saída 2]]-P22 | L22: Nesher | M22: =TabelaSobras8[[#This Row],[Estoque]]*5.8575 | N22: 700 | O22: 450 | Q22: 700 PARA N25054 450 PARA M25030 | R22: Yuri | S22: 45833 | T22: =INT(TODAY()-TabelaSobras8[[#This Row],[Data do Registro inical]])
A23: N | B23: =VLOOKUP(LEFT(A23,1),Tabela5[],2,0) | C23: EUCADUR NT - 2,5MM | D23: 795 | E23: 379 | F23: =TEXT(TabelaSobras8[[#This Row],[Comprimento Sobras (mm)]],0) & " X " & TEXT(E23,0) | G23: =(TabelaSobras8[[#This Row],[Comprimento Sobras (mm)]]*E23/1000000) | H23: 300 | I23: =IF(TabelaSobras8[[#This Row],[Estoque]]<=$V$2,$U$4,$U$5) | J23: =TabelaSobras8[[#This Row],[Quantidade de Sobra INICIAL]]-K23 | K23: =TabelaSobras8[[#This Row],[Quantidade de Sobra INICIAL]]-TabelaSobras8[[#This Row],[Saída]]-TabelaSobras8[[#This Row],[Saída 2]]-P23 | L23: Nesher | M23: =TabelaSobras8[[#This Row],[Estoque]]*5.8575 | N23: 78 | O23: 222 | Q23: 78 - RECORTE N25050 222- M25027 | R23: Yuri | S23: 45833 | T23: =INT(TODAY()-TabelaSobras8[[#This Row],[Data do Registro inical]])
A24: N | B24: =VLOOKUP(LEFT(A24,1),Tabela5[],2,0) | C24: EUCADUR FRJ - 2,5MM | D24: 695 | E24: 285 | F24: =TEXT(TabelaSobras8[[#This Row],[Comprimento Sobras (mm)]],0) & " X " & TEXT(E24,0) | G24: =(TabelaSobras8[[#This Row],[Comprimento Sobras (mm)]]*E24/1000000) | H24: 57 | I24: =IF(TabelaSobras8[[#This Row],[Estoque]]<=$V$2,$U$4,$U$5) | J24: =TabelaSobras8[[#This Row],[Quantidade de Sobra INICIAL]]-K24 | K24: =TabelaSobras8[[#This Row],[Quantidade de Sobra INICIAL]]-TabelaSobras8[[#This Row],[Saída]]-TabelaSobras8[[#This Row],[Saída 2]]-P24 | L24: Nesher | M24: =TabelaSobras8[[#This Row],[Estoque]]*5.8575 | N24: 57 | Q24: N25056 | R24: Yuri | S24: 45778 | T24: =INT(TODAY()-TabelaSobras8[[#This Row],[Data do Registro inical]])
A25: M25026 M25028 | B25: =VLOOKUP(LEFT(A25,1),Tabela5[],2,0) | C25: EUCADUR NT - 2,5MM | D25: 695 | E25: 317 | F25: =TEXT(TabelaSobras8[[#This Row],[Comprimento Sobras (mm)]],0) & " X " & TEXT(E25,0) | G25: =(TabelaSobras8[[#This Row],[Comprimento Sobras (mm)]]*E25/1000000) | H25: 665 | I25: =IF(TabelaSobras8[[#This Row],[Estoque]]<=$V$2,$U$4,$U$5) | J25: =TabelaSobras8[[#This Row],[Quantidade de Sobra INICIAL]]-K25 | K25: =TabelaSobras8[[#This Row],[Quantidade de Sobra INICIAL]]-TabelaSobras8[[#This Row],[Saída]]-TabelaSobras8[[#This Row],[Saída 2]]-P25 | L25: Nesher | M25: =TabelaSobras8[[#This Row],[Estoque]]*5.8575 | N25: 665 | Q25: N25052 | R25: Yuri | S25: 45840 | T25: =INT(TODAY()-TabelaSobras8[[#This Row],[Data do Registro inical]])
A26: M25026 | B26: =VLOOKUP(LEFT(A26,1),Tabela5[],2,0) | C26: EUCADUR NT - 2,5MM | D26: 597 | E26: 398 | F26: =TEXT(TabelaSobras8[[#This Row],[Comprimento Sobras (mm)]],0) & " X " & TEXT(E26,0) | G26: =(TabelaSobras8[[#This Row],[Comprimento Sobras (mm)]]*E26/1000000) | H26: 135 | I26: =IF(TabelaSobras8[[#This Row],[Estoque]]<=$V$2,$U$4,$U$5) | J26: =TabelaSobras8[[#This Row],[Quantidade de Sobra INICIAL]]-K26 | K26: =TabelaSobras8[[#This Row],[Quantidade de Sobra INICIAL]]-TabelaSobras8[[#This Row],[Saída]]-TabelaSobras8[[#This Row],[Saída 2]]-P26 | L26: Nesher | M26: =TabelaSobras8[[#This Row],[Estoque]]*5.8575 | N26: 135 | Q26: N2505203,N2505303 | R26: Yuri | S26: 45845 | T26: =INT(TODAY()-TabelaSobras8[[#This Row],[Data do Registro inical]])
A27: M25028 | B27: =VLOOKUP(LEFT(A27,1),Tabela5[],2,0) | C27: EUCADUR NT - 2,5MM | D27: 695 | E27: 195 | F27: =TEXT(TabelaSobras8[[#This Row],[Comprimento Sobras (mm)]],0) & " X " & TEXT(E27,0) | G27: =(TabelaSobras8[[#This Row],[Comprimento Sobras (mm)]]*E27/1000000) | H27: 408 | I27: =IF(TabelaSobras8[[#This Row],[Estoque]]<=$V$2,$U$4,$U$5) | J27: =TabelaSobras8[[#This Row],[Quantidade de Sobra INICIAL]]-K27 | K27: =TabelaSobras8[[#This Row],[Quantidade de Sobra INICIAL]]-TabelaSobras8[[#This Row],[Saída]]-TabelaSobras8[[#This Row],[Saída 2]]-P27 | L27: Nesher | M27: =TabelaSobras8[[#This Row],[Estoque]]*5.8575 | N27: 408 | Q27: N2505203,N2505303 | R27: Yuri | S27: 45845 | T27: =INT(TODAY()-TabelaSobras8[[#This Row],[Data do Registro inical]])
A28: N25053 | B28: =VLOOKUP(LEFT(A28,1),Tabela5[],2,0) | C28: EUCADUR NT - 2,5MM | D28: 695 | E28: 317 | F28: =TEXT(TabelaSobras8[[#This Row],[Comprimento Sobras (mm)]],0) & " X " & TEXT(E28,0) | G28: =(TabelaSobras8[[#This Row],[Comprimento Sobras (mm)]]*E28/1000000) | H28: 72 | I28: =IF(TabelaSobras8[[#This Row],[Estoque]]<=$V$2,$U$4,$U$5) | J28: =TabelaSobras8[[#This Row],[Quantidade de Sobra INICIAL]]-K28 | K28: =TabelaSobras8[[#This Row],[Quantidade de Sobra INICIAL]]-TabelaSobras8[[#This Row],[Saída]]-TabelaSobras8[[#This Row],[Saída 2]]-P28 | L28: Nesher | M28: =TabelaSobras8[[#This Row],[Estoque]]*5.8575 | N28: 72 | Q28: N25060 | R28: Yuri | S28: 45852 | T28: =INT(TODAY()-TabelaSobras8[[#This Row],[Data do Registro inical]])
A29: M25031 | B29: =VLOOKUP(LEFT(A29,1),Tabela5[],2,0) | C29: EUCADUR NT - 2,5MM | D29: 695 | E29: 317 | F29: =TEXT(TabelaSobras8[[#This Row],[Comprimento Sobras (mm)]],0) & " X " & TEXT(E29,0) | G29: =(TabelaSobras8[[#This Row],[Comprimento Sobras (mm)]]*E29/1000000) | H29: 222 | I29: =IF(TabelaSobras8[[#This Row],[Estoque]]<=$V$2,$U$4,$U$5) | J29: =TabelaSobras8[[#This Row],[Quantidade de Sobra INICIAL]]-K29 | K29: =TabelaSobras8[[#This Row],[Quantidade de Sobra INICIAL]]-TabelaSobras8[[#This Row],[Saída]]-TabelaSobras8[[#This Row],[Saída 2]]-P29 | L29: Nesher | M29: =TabelaSobras8[[#This Row],[Estoque]]*5.8575 | N29: 222 | Q29: N25060 | R29: Yuri | S29: 45852 | T29: =INT(TODAY()-TabelaSobras8[[#This Row],[Data do Registro inical]])
A30: M25037 | B30: =VLOOKUP(LEFT(A30,1),Tabela5[],2,0) | C30: EUCADUR FRJ - 2,5MM | D30: 1190 | E30: 312 | F30: =TEXT(TabelaSobras8[[#This Row],[Comprimento Sobras (mm)]],0) & " X " & TEXT(E30,0) | G30: =(TabelaSobras8[[#This Row],[Comprimento Sobras (mm)]]*E30/1000000) | H30: 70 | I30: =IF(TabelaSobras8[[#This Row],[Estoque]]<=$V$2,$U$4,$U$5) | J30: =TabelaSobras8[[#This Row],[Quantidade de Sobra INICIAL]]-K30 | K30: =TabelaSobras8[[#This Row],[Quantidade de Sobra INICIAL]]-TabelaSobras8[[#This Row],[Saída]]-TabelaSobras8[[#This Row],[Saída 2]]-P30 | L30: Multilínea | M30: =TabelaSobras8[[#This Row],[Estoque]]*5.8575 | N30: 70 | Q30: ENVIAR P/NESHER | R30: Yuri | S30: 45881 | T30: =INT(TODAY()-TabelaSobras8[[#This Row],[Data do Registro inical]])
A31: N | B31: =VLOOKUP(LEFT(A31,1),Tabela5[],2,0) | C31: DURATREE -2,5MM | D31: 695 | E31: 285 | F31: =TEXT(TabelaSobras8[[#This Row],[Comprimento Sobras (mm)]],0) & " X " & TEXT(E31,0) | G31: =(TabelaSobras8[[#This Row],[Comprimento Sobras (mm)]]*E31/1000000) | H31: 360 | I31: =IF(TabelaSobras8[[#This Row],[Estoque]]<=$V$2,$U$4,$U$5) | J31: =TabelaSobras8[[#This Row],[Quantidade de Sobra INICIAL]]-K31 | K31: =TabelaSobras8[[#This Row],[Quantidade de Sobra INICIAL]]-TabelaSobras8[[#This Row],[Saída]]-TabelaSobras8[[#This Row],[Saída 2]]-P31 | L31: Nesher | M31: =TabelaSobras8[[#This Row],[Estoque]]*5.8575 | N31: 360 | Q31: VENDIDO | R31: Yuri | S31: 45833 | T31: =INT(TODAY()-TabelaSobras8[[#This Row],[Data do Registro inical]])
A32: N25051 | B32: =VLOOKUP(LEFT(A32,1),Tabela5[],2,0) | C32: EUCADUR FRJ - 2,5MM | D32: 540 | E32: 398 | F32: =TEXT(TabelaSobras8[[#This Row],[Comprimento Sobras (mm)]],0) & " X " & TEXT(E32,0) | G32: =(TabelaSobras8[[#This Row],[Comprimento Sobras (mm)]]*E32/1000000) | H32: 300 | I32: =IF(TabelaSobras8[[#This Row],[Estoque]]<=$V$2,$U$4,$U$5) | J32: =TabelaSobras8[[#This Row],[Quantidade de Sobra INICIAL]]-K32 | K32: =TabelaSobras8[[#This Row],[Quantidade de Sobra INICIAL]]-TabelaSobras8[[#This Row],[Saída]]-TabelaSobras8[[#This Row],[Saída 2]]-P32 | L32: Nesher | M32: =TabelaSobras8[[#This Row],[Estoque]]*5.8575 | N32: 300 | Q32: N2505201,N2505202 | R32: Yuri | S32: 45849 | T32: =INT(TODAY()-TabelaSobras8[[#This Row],[Data do Registro inical]])
A33: N25054 | B33: =VLOOKUP(LEFT(A33,1),Tabela5[],2,0) | C33: EUCADUR FRJ - 2,5MM | D33: 329 | E33: 398 | F33: =TEXT(TabelaSobras8[[#This Row],[Comprimento Sobras (mm)]],0) & " X " & TEXT(E33,0) | G33: =(TabelaSobras8[[#This Row],[Comprimento Sobras (mm)]]*E33/1000000) | H33: 448 | I33: =IF(TabelaSobras8[[#This Row],[Estoque]]<=$V$2,$U$4,$U$5) | J33: =TabelaSobras8[[#This Row],[Quantidade de Sobra INICIAL]]-K33 | K33: =TabelaSobras8[[#This Row],[Quantidade de Sobra INICIAL]]-TabelaSobras8[[#This Row],[Saída]]-TabelaSobras8[[#This Row],[Saída 2]]-P33 | L33: Nesher | M33: =TabelaSobras8[[#This Row],[Estoque]]*5.8575 | N33: 400 | O33: 48 | Q33: I2503102,I2503104 M25032 | R33: Yuri | S33: 45848 | T33: =INT(TODAY()-TabelaSobras8[[#This Row],[Data do Registro inical]])
A34: I25031 | B34: =VLOOKUP(LEFT(A34,1),Tabela5[],2,0) | C34: EUCADUR FRJ - 2,5MM | D34: 695 | E34: 375 | F34: =TEXT(TabelaSobras8[[#This Row],[Comprimento Sobras (mm)]],0) & " X " & TEXT(E34,0) | G34: =(TabelaSobras8[[#This Row],[Comprimento Sobras (mm)]]*E34/1000000) | H34: 85 | I34: =IF(TabelaSobras8[[#This Row],[Estoque]]<=$V$2,$U$4,$U$5) | J34: =TabelaSobras8[[#This Row],[Quantidade de Sobra INICIAL]]-K34 | K34: =TabelaSobras8[[#This Row],[Quantidade de Sobra INICIAL]]-TabelaSobras8[[#This Row],[Saída]]-TabelaSobras8[[#This Row],[Saída 2]]-P34 | L34: Nesher | M34: =TabelaSobras8[[#This Row],[Estoque]]*5.8575 | N34: 85 | Q34: N25056 | R34: Yuri | S34: 45849 | T34: =INT(TODAY()-TabelaSobras8[[#This Row],[Data do Registro inical]])
A35: N25054 | B35: =VLOOKUP(LEFT(A35,1),Tabela5[],2,0) | C35: EUCADUR FRJ - 2,5MM | D35: 795 | E35: 387 | F35: =TEXT(TabelaSobras8[[#This Row],[Comprimento Sobras (mm)]],0) & " X " & TEXT(E35,0) | G35: =(TabelaSobras8[[#This Row],[Comprimento Sobras (mm)]]*E35/1000000) | H35: 700 | I35: =IF(TabelaSobras8[[#This Row],[Estoque]]<=$V$2,$U$4,$U$5) | J35: =TabelaSobras8[[#This Row],[Quantidade de Sobra INICIAL]]-K35 | K35: =TabelaSobras8[[#This Row],[Quantidade de Sobra INICIAL]]-TabelaSobras8[[#This Row],[Saída]]-TabelaSobras8[[#This Row],[Saída 2]]-P35 | L35: Nesher | M35: =TabelaSobras8[[#This Row],[Estoque]]*5.8575 | N35: 700 | Q35: RECORTE NO N25056 | R35: Yuri | S35: 45853 | T35: =INT(TODAY()-TabelaSobras8[[#This Row],[Data do Registro inical]])
A36: N25054 | B36: =VLOOKUP(LEFT(A36,1),Tabela5[],2,0) | C36: EUCADUR FRJ - 2,5MM | D36: 729 | E36: 398 | F36: =TEXT(TabelaSobras8[[#This Row],[Comprimento Sobras (mm)]],0) & " X " & TEXT(E36,0) | G36: =(TabelaSobras8[[#This Row],[Comprimento Sobras (mm)]]*E36/1000000) | H36: 350 | I36: =IF(TabelaSobras8[[#This Row],[Estoque]]<=$V$2,$U$4,$U$5) | J36: =TabelaSobras8[[#This Row],[Quantidade de Sobra INICIAL]]-K36 | K36: =TabelaSobras8[[#This Row],[Quantidade de Sobra INICIAL]]-TabelaSobras8[[#This Row],[Saída]]-TabelaSobras8[[#This Row],[Saída 2]]-P36 | L36: Nesher | M36: =TabelaSobras8[[#This Row],[Estoque]]*5.8575 | N36: 350 | Q36: recorte N25056 | R36: Yuri | S36: 45853 | T36: =INT(TODAY()-TabelaSobras8[[#This Row],[Data do Registro inical]])
A37: M25033 | B37: =VLOOKUP(LEFT(A37,1),Tabela5[],2,0) | C37: EUCADUR NT - 2,5MM | D37: 695 | E37: 317 | F37: =TEXT(TabelaSobras8[[#This Row],[Comprimento Sobras (mm)]],0) & " X " & TEXT(E37,0) | G37: =(TabelaSobras8[[#This Row],[Comprimento Sobras (mm)]]*E37/1000000) | H37: 57 | I37: =IF(TabelaSobras8[[#This Row],[Estoque]]<=$V$2,$U$4,$U$5) | J37: =TabelaSobras8[[#This Row],[Quantidade de Sobra INICIAL]]-K37 | K37: =TabelaSobras8[[#This Row],[Quantidade de Sobra INICIAL]]-TabelaSobras8[[#This Row],[Saída]]-TabelaSobras8[[#This Row],[Saída 2]]-P37 | L37: Nesher | M37: =TabelaSobras8[[#This Row],[Estoque]]*5.8575 | N37: 57 | Q37: N25060 | R37: Yuri | S37: 45861 | T37: =INT(TODAY()-TabelaSobras8[[#This Row],[Data do Registro inical]])
A38: M25033 | B38: =VLOOKUP(LEFT(A38,1),Tabela5[],2,0) | C38: EUCADUR NT - 2,5MM | D38: 695 | E38: 465 | F38: =TEXT(TabelaSobras8[[#This Row],[Comprimento Sobras (mm)]],0) & " X " & TEXT(E38,0) | G38: =(TabelaSobras8[[#This Row],[Comprimento Sobras (mm)]]*E38/1000000) | H38: 236 | I38: =IF(TabelaSobras8[[#This Row],[Estoque]]<=$V$2,$U$4,$U$5) | J38: =TabelaSobras8[[#This Row],[Quantidade de Sobra INICIAL]]-K38 | K38: =TabelaSobras8[[#This Row],[Quantidade de Sobra INICIAL]]-TabelaSobras8[[#This Row],[Saída]]-TabelaSobras8[[#This Row],[Saída 2]]-P38 | L38: Nesher | M38: =TabelaSobras8[[#This Row],[Estoque]]*5.8575 | N38: 236 | Q38: N25060 | R38: Yuri | S38: 45861 | T38: =INT(TODAY()-TabelaSobras8[[#This Row],[Data do Registro inical]])
A39: M25031 | B39: =VLOOKUP(LEFT(A39,1),Tabela5[],2,0) | C39: EUCADUR NT - 2,5MM | D39: 527 | E39: 418 | F39: =TEXT(TabelaSobras8[[#This Row],[Comprimento Sobras (mm)]],0) & " X " & TEXT(E39,0) | G39: =(TabelaSobras8[[#This Row],[Comprimento Sobras (mm)]]*E39/1000000) | H39: 20 | I39: =IF(TabelaSobras8[[#This Row],[Estoque]]<=$V$2,$U$4,$U$5) | J39: =TabelaSobras8[[#This Row],[Quantidade de Sobra INICIAL]]-K39 | K39: =TabelaSobras8[[#This Row],[Quantidade de Sobra INICIAL]]-TabelaSobras8[[#This Row],[Saída]]-TabelaSobras8[[#This Row],[Saída 2]]-P39 | L39: Nesher | M39: =TabelaSobras8[[#This Row],[Estoque]]*5.8575 | N39: 20 | R39: Yuri | S39: 45852 | T39: =INT(TODAY()-TabelaSobras8[[#This Row],[Data do Registro inical]])
A40: M25031 | B40: =VLOOKUP(LEFT(A40,1),Tabela5[],2,0) | C40: EUCADUR NT - 2,5MM | D40: 695 | E40: 337 | F40: =TEXT(TabelaSobras8[[#This Row],[Comprimento Sobras (mm)]],0) & " X " & TEXT(E40,0) | G40: =(TabelaSobras8[[#This Row],[Comprimento Sobras (mm)]]*E40/1000000) | H40: 21 | I40: =IF(TabelaSobras8[[#This Row],[Estoque]]<=$V$2,$U$4,$U$5) | J40: =TabelaSobras8[[#This Row],[Quantidade de Sobra INICIAL]]-K40 | K40: =TabelaSobras8[[#This Row],[Quantidade de Sobra INICIAL]]-TabelaSobras8[[#This Row],[Saída]]-TabelaSobras8[[#This Row],[Saída 2]]-P40 | L40: Nesher | M40: =TabelaSobras8[[#This Row],[Estoque]]*5.8575 | N40: 21 | R40: Yuri | S40: 45852 | T40: =INT(TODAY()-TabelaSobras8[[#This Row],[Data do Registro inical]])
A41: N | B41: =VLOOKUP(LEFT(A41,1),Tabela5[],2,0) | C41: EUCADUR NT - 2,5MM | D41: 540 | E41: 398 | F41: =TEXT(TabelaSobras8[[#This Row],[Comprimento Sobras (mm)]],0) & " X " & TEXT(E41,0) | G41: =(TabelaSobras8[[#This Row],[Comprimento Sobras (mm)]]*E41/1000000) | H41: 600 | I41: =IF(TabelaSobras8[[#This Row],[Estoque]]<=$V$2,$U$4,$U$5) | J41: =TabelaSobras8[[#This Row],[Quantidade de Sobra INICIAL]]-K41 | K41: =TabelaSobras8[[#This Row],[Quantidade de Sobra INICIAL]]-TabelaSobras8[[#This Row],[Saída]]-TabelaSobras8[[#This Row],[Saída 2]]-P41 | L41: Nesher | M41: =TabelaSobras8[[#This Row],[Estoque]]*5.8575 | N41: 600 | Q41: N25062 | R41: Yuri | S41: 45863 | T41: =INT(TODAY()-TabelaSobras8[[#This Row],[Data do Registro inical]])
...

Sheet Controle de Sobras MDF
U1: 0 | V1: Aproveitada | W1: Disponível | X1: média de dias | Y1: APROVEITADA
A2: Lote de Origem | B2: Fábrica | C2: Tipo de Chapa/COR | D2: Valor por m² | E2: Comprimento Sobras (mm) | F2: Largura Sobras (mm) | G2: Peça | H2: M² Sobras | I2: Quantidade de Sobra | J2: Status da Sobra | K2: Quantidade Aproveitada | L2: Estoque | M2: Local de Armazenamento | N2: M² Disponível | O2: Saída | P2: Saída 2 | Q2: Reaproveitada em OP | R2: Responsável pelo Registro | S2: Data do Registro inicial | T2: Dias parados | X2: =AVERAGEIF(TabelaSobras[Status da Sobra], "Disponível",TabelaSobras[Dias parados]) | Y2: =SUM(TabelaSobras[Quantidade Aproveitada])
A3: N2507901 | B3: =VLOOKUP(LEFT(A3,1),Tabela5[],2,0) | C3: MDF - 15MM | D3: =VLOOKUP(TabelaSobras[[#This Row],[Tipo de Chapa/COR]],'PREÇOS MDF'!$A$7:$B$10,2,0) | E3: 343 | F3: 297 | G3: =TabelaSobras[[#This Row],[Comprimento Sobras (mm)]] & " X " & F3 | H3: =(TabelaSobras[[#This Row],[Comprimento Sobras (mm)]]*F3/1000000) | I3: 310 | J3: =IF(TabelaSobras[[#This Row],[Estoque]]<=$U$1,$V$1,$W$1) | K3: =TabelaSobras[[#This Row],[Quantidade de Sobra]]-L3 | L3: =TabelaSobras[[#This Row],[Quantidade de Sobra]]-TabelaSobras[[#This Row],[Saída]]-TabelaSobras[[#This Row],[Saída 2]] | M3: Nesher | N3: =TabelaSobras[[#This Row],[M² Sobras]]*L3 | O3: 310 | Q3: N2507902 | R3: Yuri | S3: 45916 | T3: =TODAY()-TabelaSobras[[#This Row],[Data do Registro inicial]]
A4: N2507904 | B4: =VLOOKUP(LEFT(A4,1),Tabela5[],2,0) | C4: MDF - 15MM | D4: =VLOOKUP(TabelaSobras[[#This Row],[Tipo de Chapa/COR]],'PREÇOS MDF'!$A$7:$B$10,2,0) | E4: 343 | F4: 297 | G4: =TabelaSobras[[#This Row],[Comprimento Sobras (mm)]] & " X " & F4 | H4: =(TabelaSobras[[#This Row],[Comprimento Sobras (mm)]]*F4/1000000) | I4: 60 | J4: =IF(TabelaSobras[[#This Row],[Estoque]]<=$U$1,$V$1,$W$1) | K4: =TabelaSobras[[#This Row],[Quantidade de Sobra]]-L4 | L4: =TabelaSobras[[#This Row],[Quantidade de Sobra]]-TabelaSobras[[#This Row],[Saída]]-TabelaSobras[[#This Row],[Saída 2]] | M4: Nesher | N4: =TabelaSobras[[#This Row],[M² Sobras]]*L4 | O4: 60 | Q4: N2507902 | R4: Yuri | S4: 45916 | T4: =TODAY()-TabelaSobras[[#This Row],[Data do Registro inicial]]
A5: N | B5: =VLOOKUP(LEFT(A5,1),Tabela5[],2,0) | C5: MDF - 15MM | D5: =VLOOKUP(TabelaSobras[[#This Row],[Tipo de Chapa/COR]],'PREÇOS MDF'!$A$7:$B$10,2,0) | E5: 400 | F5: 263 | G5: =TabelaSobras[[#This Row],[Comprimento Sobras (mm)]] & " X " & F5 | H5: =(TabelaSobras[[#This Row],[Comprimento Sobras (mm)]]*F5/1000000) | I5: 160 | J5: =IF(TabelaSobras[[#This Row],[Estoque]]<=$U$1,$V$1,$W$1) | K5: =TabelaSobras[[#This Row],[Quantidade de Sobra]]-L5 | L5: =TabelaSobras[[#This Row],[Quantidade de Sobra]]-TabelaSobras[[#This Row],[Saída]]-TabelaSobras[[#This Row],[Saída 2]] | M5: Nesher | N5: =TabelaSobras[[#This Row],[M² Sobras]]*L5 | O5: 160 | Q5: N2507905 | R5: Yuri | S5: 45924 | T5: =TODAY()-TabelaSobras[[#This Row],[Data do Registro inicial]]
A6: N | B6: =VLOOKUP(LEFT(A6,1),Tabela5[],2,0) | C6: MDF - 15MM | D6: =VLOOKUP(TabelaSobras[[#This Row],[Tipo de Chapa/COR]],'PREÇOS MDF'!$A$7:$B$10,2,0) | E6: 400 | F6: 263 | G6: =TabelaSobras[[#This Row],[Comprimento Sobras (mm)]] & " X " & F6 | H6: =(TabelaSobras[[#This Row],[Comprimento Sobras (mm)]]*F6/1000000) | I6: =23+40 | J6: =IF(TabelaSobras[[#This Row],[Estoque]]<=$U$1,$V$1,$W$1) | K6: =TabelaSobras[[#This Row],[Quantidade de Sobra]]-L6 | L6: =TabelaSobras[[#This Row],[Quantidade de Sobra]]-TabelaSobras[[#This Row],[Saída]]-TabelaSobras[[#This Row],[Saída 2]] | M6: Nesher | N6: =TabelaSobras[[#This Row],[M² Sobras]]*L6 | O6: 32 | P6: 31 | Q6: N2508103 N2508202 | R6: Yuri | S6: 45924 | T6: =TODAY()-TabelaSobras[[#This Row],[Data do Registro inicial]]
A7: N2508001 | B7: =VLOOKUP(LEFT(A7,1),Tabela5[],2,0) | C7: MDF - 15MM | D7: =VLOOKUP(TabelaSobras[[#This Row],[Tipo de Chapa/COR]],'PREÇOS MDF'!$A$7:$B$10,2,0) | E7: 2750 | F7: 1050 | G7: =TabelaSobras[[#This Row],[Comprimento Sobras (mm)]] & " X " & F7 | H7: =(TabelaSobras[[#This Row],[Comprimento Sobras (mm)]]*F7/1000000) | I7: 1 | J7: =IF(TabelaSobras[[#This Row],[Estoque]]<=$U$1,$V$1,$W$1) | K7: =TabelaSobras[[#This Row],[Quantidade de Sobra]]-L7 | L7: =TabelaSobras[[#This Row],[Quantidade de Sobra]]-TabelaSobras[[#This Row],[Saída]]-TabelaSobras[[#This Row],[Saída 2]] | M7: Nesher | N7: =TabelaSobras[[#This Row],[M² Sobras]]*L7 | O7: 1 | Q7: RECORTE N2508001 | R7: Yuri | S7: 45924 | T7: =TODAY()-TabelaSobras[[#This Row],[Data do Registro inicial]]
A8: N2508104 | B8: =VLOOKUP(LEFT(A8,1),Tabela5[],2,0) | C8: MDF - 15MM | D8: 400 | E8: 400 | F8: 263 | G8: =TabelaSobras[[#This Row],[Comprimento Sobras (mm)]] & " X " & F8 | H8: =(TabelaSobras[[#This Row],[Comprimento Sobras (mm)]]*F8/1000000) | I8: 24 | J8: =IF(TabelaSobras[[#This Row],[Estoque]]<=$U$1,$V$1,$W$1) | K8: =TabelaSobras[[#This Row],[Quantidade de Sobra]]-L8 | L8: =TabelaSobras[[#This Row],[Quantidade de Sobra]]-TabelaSobras[[#This Row],[Saída]]-TabelaSobras[[#This Row],[Saída 2]] | M8: Nesher | N8: =TabelaSobras[[#This Row],[M² Sobras]]*L8 | O8: 24 | Q8: N2508202 | R8: Yuri | S8: 45926 | T8: =TODAY()-TabelaSobras[[#This Row],[Data do Registro inicial]]
A9: N2508105 | B9: =VLOOKUP(LEFT(A9,1),Tabela5[],2,0) | C9: MDF - 15MM | D9: =VLOOKUP(TabelaSobras[[#This Row],[Tipo de Chapa/COR]],'PREÇOS MDF'!$A$7:$B$10,2,0) | E9: 2750 | F9: 750 | G9: =TabelaSobras[[#This Row],[Comprimento Sobras (mm)]] & " X " & F9 | H9: =(TabelaSobras[[#This Row],[Comprimento Sobras (mm)]]*F9/1000000) | I9: 1 | J9: =IF(TabelaSobras[[#This Row],[Estoque]]<=$U$1,$V$1,$W$1) | K9: =TabelaSobras[[#This Row],[Quantidade de Sobra]]-L9 | L9: =TabelaSobras[[#This Row],[Quantidade de Sobra]]-TabelaSobras[[#This Row],[Saída]]-TabelaSobras[[#This Row],[Saída 2]] | M9: Nesher | N9: =TabelaSobras[[#This Row],[M² Sobras]]*L9 | O9: 1 | R9: Yuri | S9: 45926 | T9: =TODAY()-TabelaSobras[[#This Row],[Data do Registro inicial]]
A10: N250820 | B10: =VLOOKUP(LEFT(A10,1),Tabela5[],2,0) | C10: MDF - 15MM | D10: =VLOOKUP(TabelaSobras[[#This Row],[Tipo de Chapa/COR]],'PREÇOS MDF'!$A$7:$B$10,2,0) | E10: 400 | F10: 263 | G10: =TabelaSobras[[#This Row],[Comprimento Sobras (mm)]] & " X " & F10 | H10: =(TabelaSobras[[#This Row],[Comprimento Sobras (mm)]]*F10/1000000) | I10: =19+17+58 | J10: =IF(TabelaSobras[[#This Row],[Estoque]]<=$U$1,$V$1,$W$1) | K10: =TabelaSobras[[#This Row],[Quantidade de Sobra]]-L10 | L10: =TabelaSobras[[#This Row],[Quantidade de Sobra]]-TabelaSobras[[#This Row],[Saída]]-TabelaSobras[[#This Row],[Saída 2]] | M10: Nesher | N10: =TabelaSobras[[#This Row],[M² Sobras]]*L10 | O10: 94 | Q10: N2508306 | R10: Yuri | S10: 45930 | T10: =TODAY()-TabelaSobras[[#This Row],[Data do Registro inicial]]
A11: N2508202 | B11: =VLOOKUP(LEFT(A11,1),Tabela5[],2,0) | C11: MDF - 15MM | D11: =VLOOKUP(TabelaSobras[[#This Row],[Tipo de Chapa/COR]],'PREÇOS MDF'!$A$7:$B$10,2,0) | E11: 2200 | F11: 500 | G11: =TabelaSobras[[#This Row],[Comprimento Sobras (mm)]] & " X " & F11 | H11: =(TabelaSobras[[#This Row],[Comprimento Sobras (mm)]]*F11/1000000) | I11: 1 | J11: =IF(TabelaSobras[[#This Row],[Estoque]]<=$U$1,$V$1,$W$1) | K11: =TabelaSobras[[#This Row],[Quantidade de Sobra]]-L11 | L11: =TabelaSobras[[#This Row],[Quantidade de Sobra]]-TabelaSobras[[#This Row],[Saída]]-TabelaSobras[[#This Row],[Saída 2]] | M11: Nesher | N11: =TabelaSobras[[#This Row],[M² Sobras]]*L11 | O11: 1 | R11: Yuri | S11: 45930 | T11: =TODAY()-TabelaSobras[[#This Row],[Data do Registro inicial]]
A12: N2508303 | B12: =VLOOKUP(LEFT(A12,1),Tabela5[],2,0) | C12: MDF - 15MM | D12: =VLOOKUP(TabelaSobras[[#This Row],[Tipo de Chapa/COR]],'PREÇOS MDF'!$A$7:$B$10,2,0) | E12: 400 | F12: 263 | G12: =TabelaSobras[[#This Row],[Comprimento Sobras (mm)]] & " X " & F12 | H12: =(TabelaSobras[[#This Row],[Comprimento Sobras (mm)]]*F12/1000000) | I12: =249+203+114 | J12: =IF(TabelaSobras[[#This Row],[Estoque]]<=$U$1,$V$1,$W$1) | K12: =TabelaSobras[[#This Row],[Quantidade de Sobra]]-L12 | L12: =TabelaSobras[[#This Row],[Quantidade de Sobra]]-TabelaSobras[[#This Row],[Saída]]-TabelaSobras[[#This Row],[Saída 2]] | M12: Nesher | N12: =TabelaSobras[[#This Row],[M² Sobras]]*L12 | O12: 566 | Q12: N2508306 | R12: Yuri | S12: 45931 | T12: =TODAY()-TabelaSobras[[#This Row],[Data do Registro inicial]]
A13: L FURAÇÃO ERRADA | B13: =VLOOKUP(LEFT(A13,1),Tabela5[],2,0) | C13: MDF - 15MM | D13: =VLOOKUP(TabelaSobras[[#This Row],[Tipo de Chapa/COR]],'PREÇOS MDF'!$A$7:$B$10,2,0) | E13: 313 | F13: 297 | G13: =TabelaSobras[[#This Row],[Comprimento Sobras (mm)]] & " X " & F13 | H13: =(TabelaSobras[[#This Row],[Comprimento Sobras (mm)]]*F13/1000000) | I13: 900 | J13: =IF(TabelaSobras[[#This Row],[Estoque]]<=$U$1,$V$1,$W$1) | K13: =TabelaSobras[[#This Row],[Quantidade de Sobra]]-L13 | L13: =TabelaSobras[[#This Row],[Quantidade de Sobra]]-TabelaSobras[[#This Row],[Saída]]-TabelaSobras[[#This Row],[Saída 2]] | M13: Líder | N13: =TabelaSobras[[#This Row],[M² Sobras]]*L13 | O13: 620 | P13: 280 | Q13: 280 REFUGO - 620 APROVEITADAS L2506902 | R13: Yuri | S13: 45953 | T13: =TODAY()-TabelaSobras[[#This Row],[Data do Registro inicial]]
A14: l | B14: =VLOOKUP(LEFT(A14,1),Tabela5[],2,0) | C14: MDF - 15MM | D14: =VLOOKUP(TabelaSobras[[#This Row],[Tipo de Chapa/COR]],'PREÇOS MDF'!$A$7:$B$10,2,0) | E14: 300 | F14: 2750 | G14: =TabelaSobras[[#This Row],[Comprimento Sobras (mm)]] & " X " & F14 | H14: =(TabelaSobras[[#This Row],[Comprimento Sobras (mm)]]*F14/1000000) | I14: 9 | J14: =IF(TabelaSobras[[#This Row],[Estoque]]<=$U$1,$V$1,$W$1) | K14: =TabelaSobras[[#This Row],[Quantidade de Sobra]]-L14 | L14: =TabelaSobras[[#This Row],[Quantidade de Sobra]]-TabelaSobras[[#This Row],[Saída]]-TabelaSobras[[#This Row],[Saída 2]] | M14: Líder | N14: =TabelaSobras[[#This Row],[M² Sobras]]*L14 | O14: 9 | Q14: L2506501 | R14: Yuri | S14: 45950 | T14: =TODAY()-TabelaSobras[[#This Row],[Data do Registro inicial]]
A15: N2508602 | B15: =VLOOKUP(LEFT(A15,1),Tabela5[],2,0) | C15: MDF - 15MM | D15: =VLOOKUP(TabelaSobras[[#This Row],[Tipo de Chapa/COR]],'PREÇOS MDF'!$A$7:$B$10,2,0) | E15: 400 | F15: 263 | G15: =TabelaSobras[[#This Row],[Comprimento Sobras (mm)]] & " X " & F15 | H15: =(TabelaSobras[[#This Row],[Comprimento Sobras (mm)]]*F15/1000000) | I15: 114 | J15: =IF(TabelaSobras[[#This Row],[Estoque]]<=$U$1,$V$1,$W$1) | K15: =TabelaSobras[[#This Row],[Quantidade de Sobra]]-L15 | L15: =TabelaSobras[[#This Row],[Quantidade de Sobra]]-TabelaSobras[[#This Row],[Saída]]-TabelaSobras[[#This Row],[Saída 2]] | M15: Nesher | N15: =TabelaSobras[[#This Row],[M² Sobras]]*L15 | O15: 114 | Q15: N2508606 | R15: Yuri | S15: 45958 | T15: =TODAY()-TabelaSobras[[#This Row],[Data do Registro inicial]]
A16: N2508603 | B16: =VLOOKUP(LEFT(A16,1),Tabela5[],2,0) | C16: MDF - 15MM | D16: =VLOOKUP(TabelaSobras[[#This Row],[Tipo de Chapa/COR]],'PREÇOS MDF'!$A$7:$B$10,2,0) | E16: 400 | F16: 263 | G16: =TabelaSobras[[#This Row],[Comprimento Sobras (mm)]] & " X " & F16 | H16: =(TabelaSobras[[#This Row],[Comprimento Sobras (mm)]]*F16/1000000) | I16: 10 | J16: =IF(TabelaSobras[[#This Row],[Estoque]]<=$U$1,$V$1,$W$1) | K16: =TabelaSobras[[#This Row],[Quantidade de Sobra]]-L16 | L16: =TabelaSobras[[#This Row],[Quantidade de Sobra]]-TabelaSobras[[#This Row],[Saída]]-TabelaSobras[[#This Row],[Saída 2]] | M16: Nesher | N16: =TabelaSobras[[#This Row],[M² Sobras]]*L16 | O16: 10 | Q16: N2508606 | R16: Yuri | S16: 45958 | T16: =TODAY()-TabelaSobras[[#This Row],[Data do Registro inicial]]
A17: N2508605 | B17: =VLOOKUP(LEFT(A17,1),Tabela5[],2,0) | C17: MDF - 15MM | D17: =VLOOKUP(TabelaSobras[[#This Row],[Tipo de Chapa/COR]],'PREÇOS MDF'!$A$7:$B$10,2,0) | E17: 400 | F17: 263 | G17: =TabelaSobras[[#This Row],[Comprimento Sobras (mm)]] & " X " & F17 | H17: =(TabelaSobras[[#This Row],[Comprimento Sobras (mm)]]*F17/1000000) | I17: =203+8 | J17: =IF(TabelaSobras[[#This Row],[Estoque]]<=$U$1,$V$1,$W$1) | K17: =TabelaSobras[[#This Row],[Quantidade de Sobra]]-L17 | L17: =TabelaSobras[[#This Row],[Quantidade de Sobra]]-TabelaSobras[[#This Row],[Saída]]-TabelaSobras[[#This Row],[Saída 2]] | M17: Nesher | N17: =TabelaSobras[[#This Row],[M² Sobras]]*L17 | O17: 211 | Q17: N2508704-05 | R17: Yuri | S17: 45961 | T17: =TODAY()-TabelaSobras[[#This Row],[Data do Registro inicial]]
A18: N2508703 | B18: =VLOOKUP(LEFT(A18,1),Tabela5[],2,0) | C18: MDF - 15MM | D18: =VLOOKUP(TabelaSobras[[#This Row],[Tipo de Chapa/COR]],'PREÇOS MDF'!$A$7:$B$10,2,0) | E18: 400 | F18: 263 | G18: =TabelaSobras[[#This Row],[Comprimento Sobras (mm)]] & " X " & F18 | H18: =(TabelaSobras[[#This Row],[Comprimento Sobras (mm)]]*F18/1000000) | I18: 37 | J18: =IF(TabelaSobras[[#This Row],[Estoque]]<=$U$1,$V$1,$W$1) | K18: =TabelaSobras[[#This Row],[Quantidade de Sobra]]-L18 | L18: =TabelaSobras[[#This Row],[Quantidade de Sobra]]-TabelaSobras[[#This Row],[Saída]]-TabelaSobras[[#This Row],[Saída 2]] | M18: Nesher | N18: =TabelaSobras[[#This Row],[M² Sobras]]*L18 | O18: 37 | Q18: N2508704-05 | R18: Yuri | S18: 45964 | T18: =TODAY()-TabelaSobras[[#This Row],[Data do Registro inicial]]
A19: N2508802 | B19: =VLOOKUP(LEFT(A19,1),Tabela5[],2,0) | C19: MDF - 15MM | D19: =VLOOKUP(TabelaSobras[[#This Row],[Tipo de Chapa/COR]],'PREÇOS MDF'!$A$7:$B$10,2,0) | E19: 229 | F19: 292 | G19: =TabelaSobras[[#This Row],[Comprimento Sobras (mm)]] & " X " & F19 | H19: =(TabelaSobras[[#This Row],[Comprimento Sobras (mm)]]*F19/1000000) | I19: 108 | J19: =IF(TabelaSobras[[#This Row],[Estoque]]<=$U$1,$V$1,$W$1) | K19: =TabelaSobras[[#This Row],[Quantidade de Sobra]]-L19 | L19: =TabelaSobras[[#This Row],[Quantidade de Sobra]]-TabelaSobras[[#This Row],[Saída]]-TabelaSobras[[#This Row],[Saída 2]] | M19: Nesher | N19: =TabelaSobras[[#This Row],[M² Sobras]]*L19 | O19: 108 | Q19: N2509001 | R19: Yuri | S19: 45971 | T19: =TODAY()-TabelaSobras[[#This Row],[Data do Registro inicial]]
A20: N2508802|01|03 | B20: =VLOOKUP(LEFT(A20,1),Tabela5[],2,0) | C20: MDF - 15MM | D20: =VLOOKUP(TabelaSobras[[#This Row],[Tipo de Chapa/COR]],'PREÇOS MDF'!$A$7:$B$10,2,0) | E20: 400 | F20: 263 | G20: =TabelaSobras[[#This Row],[Comprimento Sobras (mm)]] & " X " & F20 | H20: =(TabelaSobras[[#This Row],[Comprimento Sobras (mm)]]*F20/1000000) | I20: =203+56+124 | J20: =IF(TabelaSobras[[#This Row],[Estoque]]<=$U$1,$V$1,$W$1) | K20: =TabelaSobras[[#This Row],[Quantidade de Sobra]]-L20 | L20: =TabelaSobras[[#This Row],[Quantidade de Sobra]]-TabelaSobras[[#This Row],[Saída]]-TabelaSobras[[#This Row],[Saída 2]] | M20: Nesher | N20: =TabelaSobras[[#This Row],[M² Sobras]]*L20 | O20: 107 | P20: 276 | Q20: N2508804 | N2509006 | R20: Yuri | S20: 45971 | T20: =TODAY()-TabelaSobras[[#This Row],[Data do Registro inicial]]
A21: L2507101 | B21: =VLOOKUP(LEFT(A21,1),Tabela5[],2,0) | C21: MDF - 25MM | D21: =VLOOKUP(TabelaSobras[[#This Row],[Tipo de Chapa/COR]],'PREÇOS MDF'!$A$7:$B$10,2,0) | E21: 2100 | F21: 450 | G21: =TabelaSobras[[#This Row],[Comprimento Sobras (mm)]] & " X " & F21 | H21: =(TabelaSobras[[#This Row],[Comprimento Sobras (mm)]]*F21/1000000) | I21: 50 | J21: =IF(TabelaSobras[[#This Row],[Estoque]]<=$U$1,$V$1,$W$1) | K21: =TabelaSobras[[#This Row],[Quantidade de Sobra]]-L21 | L21: =TabelaSobras[[#This Row],[Quantidade de Sobra]]-TabelaSobras[[#This Row],[Saída]]-TabelaSobras[[#This Row],[Saída 2]] | M21: Líder | N21: =TabelaSobras[[#This Row],[M² Sobras]]*L21 | O21: 50 | Q21: L2507104 | R21: Yuri | S21: 45981 | T21: =TODAY()-TabelaSobras[[#This Row],[Data do Registro inicial]]
A22: LOFT | B22: =VLOOKUP(LEFT(A22,1),Tabela5[],2,0) | C22: MDF - 15MM | D22: =VLOOKUP(TabelaSobras[[#This Row],[Tipo de Chapa/COR]],'PREÇOS MDF'!$A$7:$B$10,2,0) | E22: 420 | F22: 520 | G22: =TabelaSobras[[#This Row],[Comprimento Sobras (mm)]] & " X " & F22 | H22: =(TabelaSobras[[#This Row],[Comprimento Sobras (mm)]]*F22/1000000) | I22: 144 | J22: =IF(TabelaSobras[[#This Row],[Estoque]]<=$U$1,$V$1,$W$1) | K22: =TabelaSobras[[#This Row],[Quantidade de Sobra]]-L22 | L22: =TabelaSobras[[#This Row],[Quantidade de Sobra]]-TabelaSobras[[#This Row],[Saída]]-TabelaSobras[[#This Row],[Saída 2]] | M22: Líder | N22: =TabelaSobras[[#This Row],[M² Sobras]]*L22 | O22: 144 | Q22: RECORTE | R22: Yuri | S22: 45986 | T22: =TODAY()-TabelaSobras[[#This Row],[Data do Registro inicial]]
A23: LOFT | B23: =VLOOKUP(LEFT(A23,1),Tabela5[],2,0) | C23: MDF - 15MM | D23: =VLOOKUP(TabelaSobras[[#This Row],[Tipo de Chapa/COR]],'PREÇOS MDF'!$A$7:$B$10,2,0) | E23: 590 | F23: 525 | G23: =TabelaSobras[[#This Row],[Comprimento Sobras (mm)]] & " X " & F23 | H23: =(TabelaSobras[[#This Row],[Comprimento Sobras (mm)]]*F23/1000000) | I23: 430 | J23: =IF(TabelaSobras[[#This Row],[Estoque]]<=$U$1,$V$1,$W$1) | K23: =TabelaSobras[[#This Row],[Quantidade de Sobra]]-L23 | L23: =TabelaSobras[[#This Row],[Quantidade de Sobra]]-TabelaSobras[[#This Row],[Saída]]-TabelaSobras[[#This Row],[Saída 2]] | M23: Líder | N23: =TabelaSobras[[#This Row],[M² Sobras]]*L23 | O23: 320 | P23: 110 | Q23: L2507201 | R23: Yuri | S23: 45986 | T23: =TODAY()-TabelaSobras[[#This Row],[Data do Registro inicial]]
A24: N26017 | B24: =VLOOKUP(LEFT(A24,1),Tabela5[],2,0) | C24: MDF - 15MM | D24: =VLOOKUP(TabelaSobras[[#This Row],[Tipo de Chapa/COR]],'PREÇOS MDF'!$A$7:$B$10,2,0) | E24: 400 | F24: 263 | G24: =TabelaSobras[[#This Row],[Comprimento Sobras (mm)]] & " X " & F24 | H24: =(TabelaSobras[[#This Row],[Comprimento Sobras (mm)]]*F24/1000000) | I24: =574+32 | J24: =IF(TabelaSobras[[#This Row],[Estoque]]<=$U$1,$V$1,$W$1) | K24: =TabelaSobras[[#This Row],[Quantidade de Sobra]]-L24 | L24: =TabelaSobras[[#This Row],[Quantidade de Sobra]]-TabelaSobras[[#This Row],[Saída]]-TabelaSobras[[#This Row],[Saída 2]] | M24: Nesher | N24: =TabelaSobras[[#This Row],[M² Sobras]]*L24 | O24: 438 | P24: 168 | Q24: N26020 | R24: Yuri | S24: 46076 | T24: =TODAY()-TabelaSobras[[#This Row],[Data do Registro inicial]]
A25: N | B25: =VLOOKUP(LEFT(A25,1),Tabela5[],2,0) | C25: MDF - 15MM | D25: =VLOOKUP(TabelaSobras[[#This Row],[Tipo de Chapa/COR]],'PREÇOS MDF'!$A$7:$B$10,2,0) | G25: =TabelaSobras[[#This Row],[Comprimento Sobras (mm)]] & " X " & F25 | H25: =(TabelaSobras[[#This Row],[Comprimento Sobras (mm)]]*F25/1000000) | J25: =IF(TabelaSobras[[#This Row],[Estoque]]<=$U$1,$V$1,$W$1) | K25: =TabelaSobras[[#This Row],[Quantidade de Sobra]]-L25 | L25: =TabelaSobras[[#This Row],[Quantidade de Sobra]]-TabelaSobras[[#This Row],[Saída]]-TabelaSobras[[#This Row],[Saída 2]] | M25: Nesher | N25: =TabelaSobras[[#This Row],[M² Sobras]]*L25 | R25: Yuri | S25: 46000 | T25: =TODAY()-TabelaSobras[[#This Row],[Data do Registro inicial]]
A26: L | B26: =VLOOKUP(LEFT(A26,1),Tabela5[],2,0) | C26: MDF - 15MM | D26: =VLOOKUP(TabelaSobras[[#This Row],[Tipo de Chapa/COR]],'PREÇOS MDF'!$A$7:$B$10,2,0) | E26: 1568 | F26: 297 | G26: =TabelaSobras[[#This Row],[Comprimento Sobras (mm)]] & " X " & F26 | H26: =(TabelaSobras[[#This Row],[Comprimento Sobras (mm)]]*F26/1000000) | I26: 6 | J26: =IF(TabelaSobras[[#This Row],[Estoque]]<=$U$1,$V$1,$W$1) | K26: =TabelaSobras[[#This Row],[Quantidade de Sobra]]-L26 | L26: =TabelaSobras[[#This Row],[Quantidade de Sobra]]-TabelaSobras[[#This Row],[Saída]]-TabelaSobras[[#This Row],[Saída 2]] | M26: Líder | N26: =TabelaSobras[[#This Row],[M² Sobras]]*L26 | O26: 6 | Q26: 7492-93-94-95 | R26: Yuri | S26: 46006 | T26: =TODAY()-TabelaSobras[[#This Row],[Data do Registro inicial]]
A27: L | B27: =VLOOKUP(LEFT(A27,1),Tabela5[],2,0) | C27: MDF - 15MM | D27: =VLOOKUP(TabelaSobras[[#This Row],[Tipo de Chapa/COR]],'PREÇOS MDF'!$A$7:$B$10,2,0) | E27: 476 | F27: 297 | G27: =TabelaSobras[[#This Row],[Comprimento Sobras (mm)]] & " X " & F27 | H27: =(TabelaSobras[[#This Row],[Comprimento Sobras (mm)]]*F27/1000000) | I27: 26 | J27: =IF(TabelaSobras[[#This Row],[Estoque]]<=$U$1,$V$1,$W$1) | K27: =TabelaSobras[[#This Row],[Quantidade de Sobra]]-L27 | L27: =TabelaSobras[[#This Row],[Quantidade de Sobra]]-TabelaSobras[[#This Row],[Saída]]-TabelaSobras[[#This Row],[Saída 2]] | M27: Líder | N27: =TabelaSobras[[#This Row],[M² Sobras]]*L27 | O27: 26 | Q27: 7492-93-94-95 | R27: Yuri | S27: 46006 | T27: =TODAY()-TabelaSobras[[#This Row],[Data do Registro inicial]]
A28: V-REFUGO (14 PÇS CRÉDITO) 160 PARA 120 | B28: =VLOOKUP(LEFT(A28,1),Tabela5[],2,0) | C28: MDF - 25MM | D28: =VLOOKUP(TabelaSobras[[#This Row],[Tipo de Chapa/COR]],'PREÇOS MDF'!$A$7:$B$10,2,0) | E28: 1202 | F28: 902 | G28: =TabelaSobras[[#This Row],[Comprimento Sobras (mm)]] & " X " & F28 | H28: =(TabelaSobras[[#This Row],[Comprimento Sobras (mm)]]*F28/1000000) | I28: 15 | J28: =IF(TabelaSobras[[#This Row],[Estoque]]<=$U$1,$V$1,$W$1) | K28: =TabelaSobras[[#This Row],[Quantidade de Sobra]]-L28 | L28: =TabelaSobras[[#This Row],[Quantidade de Sobra]]-TabelaSobras[[#This Row],[Saída]]-TabelaSobras[[#This Row],[Saída 2]] | M28: Líder | N28: =TabelaSobras[[#This Row],[M² Sobras]]*L28 | O28: 15 | Q28: V2521801 | R28: Yuri | S28: 46009 | T28: =TODAY()-TabelaSobras[[#This Row],[Data do Registro inicial]]
A29: V | B29: =VLOOKUP(LEFT(A29,1),Tabela5[],2,0) | C29: MDF - 25MM | D29: =VLOOKUP(TabelaSobras[[#This Row],[Tipo de Chapa/COR]],'PREÇOS MDF'!$A$7:$B$10,2,0) | E29: 1602 | F29: 902 | G29: =TabelaSobras[[#This Row],[Comprimento Sobras (mm)]] & " X " & F29 | H29: =(TabelaSobras[[#This Row],[Comprimento Sobras (mm)]]*F29/1000000) | I29: 12 | J29: =IF(TabelaSobras[[#This Row],[Estoque]]<=$U$1,$V$1,$W$1) | K29: =TabelaSobras[[#This Row],[Quantidade de Sobra]]-L29 | L29: =TabelaSobras[[#This Row],[Quantidade de Sobra]]-TabelaSobras[[#This Row],[Saída]]-TabelaSobras[[#This Row],[Saída 2]] | M29: Líder | N29: =TabelaSobras[[#This Row],[M² Sobras]]*L29 | O29: 12 | Q29: V2521501 | R29: Yuri | S29: 46010 | T29: =TODAY()-TabelaSobras[[#This Row],[Data do Registro inicial]]
A30: N25095 | B30: =VLOOKUP(LEFT(A30,1),Tabela5[],2,0) | C30: MDF - 15MM | D30: =VLOOKUP(TabelaSobras[[#This Row],[Tipo de Chapa/COR]],'PREÇOS MDF'!$A$7:$B$10,2,0) | E30: 400 | F30: 263 | G30: =TabelaSobras[[#This Row],[Comprimento Sobras (mm)]] & " X " & F30 | H30: =(TabelaSobras[[#This Row],[Comprimento Sobras (mm)]]*F30/1000000) | I30: =220+76+53+60+243 | J30: =IF(TabelaSobras[[#This Row],[Estoque]]<=$U$1,$V$1,$W$1) | K30: =TabelaSobras[[#This Row],[Quantidade de Sobra]]-L30 | L30: =TabelaSobras[[#This Row],[Quantidade de Sobra]]-TabelaSobras[[#This Row],[Saída]]-TabelaSobras[[#This Row],[Saída 2]] | M30: Nesher | N30: =TabelaSobras[[#This Row],[M² Sobras]]*L30 | O30: 477 | P30: 175 | Q30: N26006 | N2600803 | R30: Yuri | S30: 46028 | T30: =TODAY()-TabelaSobras[[#This Row],[Data do Registro inicial]]
A31: N25094 | B31: =VLOOKUP(LEFT(A31,1),Tabela5[],2,0) | C31: MDF - 25MM | D31: =VLOOKUP(TabelaSobras[[#This Row],[Tipo de Chapa/COR]],'PREÇOS MDF'!$A$7:$B$10,2,0) | E31: 805 | F31: 450 | G31: =TabelaSobras[[#This Row],[Comprimento Sobras (mm)]] & " X " & F31 | H31: =(TabelaSobras[[#This Row],[Comprimento Sobras (mm)]]*F31/1000000) | I31: 150 | J31: =IF(TabelaSobras[[#This Row],[Estoque]]<=$U$1,$V$1,$W$1) | K31: =TabelaSobras[[#This Row],[Quantidade de Sobra]]-L31 | L31: =TabelaSobras[[#This Row],[Quantidade de Sobra]]-TabelaSobras[[#This Row],[Saída]]-TabelaSobras[[#This Row],[Saída 2]] | M31: Nesher | N31: =TabelaSobras[[#This Row],[M² Sobras]]*L31 | O31: 150 | Q31: N2600205 | R31: Yuri | S31: 46029 | T31: =TODAY()-TabelaSobras[[#This Row],[Data do Registro inicial]]
A32: N25094 | B32: =VLOOKUP(LEFT(A32,1),Tabela5[],2,0) | C32: MDF - 25MM | D32: =VLOOKUP(TabelaSobras[[#This Row],[Tipo de Chapa/COR]],'PREÇOS MDF'!$A$7:$B$10,2,0) | E32: 655 | F32: 450 | G32: =TabelaSobras[[#This Row],[Comprimento Sobras (mm)]] & " X " & F32 | H32: =(TabelaSobras[[#This Row],[Comprimento Sobras (mm)]]*F32/1000000) | I32: 150 | J32: =IF(TabelaSobras[[#This Row],[Estoque]]<=$U$1,$V$1,$W$1) | K32: =TabelaSobras[[#This Row],[Quantidade de Sobra]]-L32 | L32: =TabelaSobras[[#This Row],[Quantidade de Sobra]]-TabelaSobras[[#This Row],[Saída]]-TabelaSobras[[#This Row],[Saída 2]] | M32: Nesher | N32: =TabelaSobras[[#This Row],[M² Sobras]]*L32 | O32: 150 | Q32: N2601101 | R32: Yuri | S32: 46029 | T32: =TODAY()-TabelaSobras[[#This Row],[Data do Registro inicial]]
A33: N-SOBRAS | B33: =VLOOKUP(LEFT(A33,1),Tabela5[],2,0) | C33: MDF - 15MM | D33: =VLOOKUP(TabelaSobras[[#This Row],[Tipo de Chapa/COR]],'PREÇOS MDF'!$A$7:$B$10,2,0) | E33: 342 | F33: 297 | G33: =TabelaSobras[[#This Row],[Comprimento Sobras (mm)]] & " X " & F33 | H33: =(TabelaSobras[[#This Row],[Comprimento Sobras (mm)]]*F33/1000000) | I33: 137 | J33: =IF(TabelaSobras[[#This Row],[Estoque]]<=$U$1,$V$1,$W$1) | K33: =TabelaSobras[[#This Row],[Quantidade de Sobra]]-L33 | L33: =TabelaSobras[[#This Row],[Quantidade de Sobra]]-TabelaSobras[[#This Row],[Saída]]-TabelaSobras[[#This Row],[Saída 2]] | M33: Nesher | N33: =TabelaSobras[[#This Row],[M² Sobras]]*L33 | O33: 137 | Q33: N26022 | R33: Yuri | S33: 46104 | T33: =TODAY()-TabelaSobras[[#This Row],[Data do Registro inicial]]
A34: N2600902 | N2601903-04|N26017 | B34: =VLOOKUP(LEFT(A34,1),Tabela5[],2,0) | C34: MDF - 15MM | D34: =VLOOKUP(TabelaSobras[[#This Row],[Tipo de Chapa/COR]],'PREÇOS MDF'!$A$7:$B$10,2,0) | E34: 313 | F34: 297 | G34: =TabelaSobras[[#This Row],[Comprimento Sobras (mm)]] & " X " & F34 | H34: =(TabelaSobras[[#This Row],[Comprimento Sobras (mm)]]*F34/1000000) | I34: =90+24+189+179+132 | J34: =IF(TabelaSobras[[#This Row],[Estoque]]<=$U$1,$V$1,$W$1) | K34: =TabelaSobras[[#This Row],[Quantidade de Sobra]]-L34 | L34: =TabelaSobras[[#This Row],[Quantidade de Sobra]]-TabelaSobras[[#This Row],[Saída]]-TabelaSobras[[#This Row],[Saída 2]] | M34: Nesher | N34: =TabelaSobras[[#This Row],[M² Sobras]]*L34 | O34: 614 | Q34: KIT NOBREZA 2100 | R34: Yuri | S34: 46034 | T34: =TODAY()-TabelaSobras[[#This Row],[Data do Registro inicial]]
A35: N-FURAÇÃO A MAIS BALC 1 pt 3 gv120 | B35: =VLOOKUP(LEFT(A35,1),Tabela5[],2,0) | C35: MDF - 15MM | D35: =VLOOKUP(TabelaSobras[[#This Row],[Tipo de Chapa/COR]],'PREÇOS MDF'!$A$7:$B$10,2,0) | E35: 780 | F35: 500 | G35: =TabelaSobras[[#This Row],[Comprimento Sobras (mm)]] & " X " & F35 | H35: =(TabelaSobras[[#This Row],[Comprimento Sobras (mm)]]*F35/1000000) | I35: 60 | J35: =IF(TabelaSobras[[#This Row],[Estoque]]<=$U$1,$V$1,$W$1) | K35: =TabelaSobras[[#This Row],[Quantidade de Sobra]]-L35 | L35: =TabelaSobras[[#This Row],[Quantidade de Sobra]]-TabelaSobras[[#This Row],[Saída]]-TabelaSobras[[#This Row],[Saída 2]] | M35: Nesher | N35: =TabelaSobras[[#This Row],[M² Sobras]]*L35 | O35: 60 | Q35: N2604506 | R35: Yuri | S35: 46150 | T35: =TODAY()-TabelaSobras[[#This Row],[Data do Registro inicial]]
A36: N2601002 | N2600201 AO N2600204 | B36: =VLOOKUP(LEFT(A36,1),Tabela5[],2,0) | C36: MDF - 15MM | D36: =VLOOKUP(TabelaSobras[[#This Row],[Tipo de Chapa/COR]],'PREÇOS MDF'!$A$7:$B$10,2,0) | E36: 297 | F36: 319 | G36: =TabelaSobras[[#This Row],[Comprimento Sobras (mm)]] & " X " & F36 | H36: =(TabelaSobras[[#This Row],[Comprimento Sobras (mm)]]*F36/1000000) | I36: 21 | J36: =IF(TabelaSobras[[#This Row],[Estoque]]<=$U$1,$V$1,$W$1) | K36: =TabelaSobras[[#This Row],[Quantidade de Sobra]]-L36 | L36: =TabelaSobras[[#This Row],[Quantidade de Sobra]]-TabelaSobras[[#This Row],[Saída]]-TabelaSobras[[#This Row],[Saída 2]] | M36: Nesher | N36: =TabelaSobras[[#This Row],[M² Sobras]]*L36 | O36: 21 | Q36: N2601006 | R36: Yuri | S36: 46037 | T36: =TODAY()-TabelaSobras[[#This Row],[Data do Registro inicial]]
A37: N2601002 | N2600201 AO N2600204 | B37: =VLOOKUP(LEFT(A37,1),Tabela5[],2,0) | C37: MDF - 15MM | D37: =VLOOKUP(TabelaSobras[[#This Row],[Tipo de Chapa/COR]],'PREÇOS MDF'!$A$7:$B$10,2,0) | E37: 343 | F37: 297 | G37: =TabelaSobras[[#This Row],[Comprimento Sobras (mm)]] & " X " & F37 | H37: =(TabelaSobras[[#This Row],[Comprimento Sobras (mm)]]*F37/1000000) | I37: 50 | J37: =IF(TabelaSobras[[#This Row],[Estoque]]<=$U$1,$V$1,$W$1) | K37: =TabelaSobras[[#This Row],[Quantidade de Sobra]]-L37 | L37: =TabelaSobras[[#This Row],[Quantidade de Sobra]]-TabelaSobras[[#This Row],[Saída]]-TabelaSobras[[#This Row],[Saída 2]] | M37: Nesher | N37: =TabelaSobras[[#This Row],[M² Sobras]]*L37 | O37: 12 | P37: 38 | Q37: N2601006 | N2600802 | R37: Yuri | S37: 46037 | T37: =TODAY()-TabelaSobras[[#This Row],[Data do Registro inicial]]
A38: N2601002 | N2600201 AO N2600204 | B38: =VLOOKUP(LEFT(A38,1),Tabela5[],2,0) | C38: MDF - 15MM | D38: =VLOOKUP(TabelaSobras[[#This Row],[Tipo de Chapa/COR]],'PREÇOS MDF'!$A$7:$B$10,2,0) | E38: 297 | F38: 368 | G38: =TabelaSobras[[#This Row],[Comprimento Sobras (mm)]] & " X " & F38 | H38: =(TabelaSobras[[#This Row],[Comprimento Sobras (mm)]]*F38/1000000) | I38: 24 | J38: =IF(TabelaSobras[[#This Row],[Estoque]]<=$U$1,$V$1,$W$1) | K38: =TabelaSobras[[#This Row],[Quantidade de Sobra]]-L38 | L38: =TabelaSobras[[#This Row],[Quantidade de Sobra]]-TabelaSobras[[#This Row],[Saída]]-TabelaSobras[[#This Row],[Saída 2]] | M38: Nesher | N38: =TabelaSobras[[#This Row],[M² Sobras]]*L38 | O38: 24 | Q38: N2600802 | R38: Yuri | S38: 46037 | T38: =TODAY()-TabelaSobras[[#This Row],[Data do Registro inicial]]
A39: N2601007 | N2601006 | B39: =VLOOKUP(LEFT(A39,1),Tabela5[],2,0) | C39: MDF - 15MM | D39: =VLOOKUP(TabelaSobras[[#This Row],[Tipo de Chapa/COR]],'PREÇOS MDF'!$A$7:$B$10,2,0) | E39: 400 | F39: 92 | G39: =TabelaSobras[[#This Row],[Comprimento Sobras (mm)]] & " X " & F39 | H39: =(TabelaSobras[[#This Row],[Comprimento Sobras (mm)]]*F39/1000000) | I39: 87 | J39: =IF(TabelaSobras[[#This Row],[Estoque]]<=$U$1,$V$1,$W$1) | K39: =TabelaSobras[[#This Row],[Quantidade de Sobra]]-L39 | L39: =TabelaSobras[[#This Row],[Quantidade de Sobra]]-TabelaSobras[[#This Row],[Saída]]-TabelaSobras[[#This Row],[Saída 2]] | M39: Nesher | N39: =TabelaSobras[[#This Row],[M² Sobras]]*L39 | O39: 87 | Q39: N2600801 | R39: Yuri | S39: 46038 | T39: =TODAY()-TabelaSobras[[#This Row],[Data do Registro inicial]]
